Workbook

Sheet Partidos
A1: Nº | B1: Fecha | C1: Jugadores | D1: Ander | E1: Aitor A. | F1: Aitor Z. | G1: Chocarro | H1: David Culé | I1: David Ras | J1: Eddy | K1: Enrique | L1: Fer | M1: Iñaki | N1: Miguel T. | O1: Oscar | P1: Raúl | Q1: Ritxo | R1: Sixers | S1: Telmo | T1: Txus | U1: Unai | V1: Xabi | W1: Zapas | Y1: Borja | Z1: Hidalgo | AA1: Jesús | AB1: Jon A. | AC1: Ricky | AD1: Iker | AE1: Xabi BK | AF1: Pablo Bk | AG1: Lander | AH1: Javi BK | AI1: Moha BK | AJ1: Jonathan BK | AK1: Gio BK | AL1: Laura | AM1: David arg. | AN1: Íñigo | AO1: Korta | AP1: Javi Temprano | AQ1: Mikel | AR1: Antonio | AS1: Minde
A2: 1 | B2: 45932 | C2: =COUNTIF(D2:AO2,"<>") -> 12 | E2: 2 | F2: 2 | G2: 2 | J2: 1 | L2: 1 | M2: 2 | O2: 2 | R2: 1 | S2: 1 | T2: 2 | U2: 1 | AB2: 1
A3: 2 | B3: 45932 | C3: =COUNTIF(D3:AO3,"<>") -> 12 | E3: 1 | F3: 1 | G3: 1 | J3: 2 | L3: 2 | M3: 1 | O3: 1 | R3: 2 | S3: 2 | T3: 1 | U3: 2 | AB3: 2
A4: 3 | B4: 45937 | C4: =COUNTIF(D4:AO4,"<>") -> 12 | E4: 2 | G4: 2 | H4: 1 | J4: 2 | K4: 2 | L4: 1 | O4: 1 | R4: 2 | T4: 1 | U4: 1 | AB4: 2 | AD4: 1
A5: 4 | B5: 45937 | C5: =COUNTIF(D5:AO5,"<>") -> 12 | E5: 2 | G5: 2 | H5: 1 | J5: 2 | K5: 2 | L5: 1 | O5: 1 | R5: 2 | T5: 1 | U5: 1 | AB5: 2 | AD5: 1
A6: 5 | B6: 45937 | C6: =COUNTIF(D6:AO6,"<>") -> 12 | E6: 1 | G6: 1 | H6: 2 | J6: 1 | K6: 1 | L6: 2 | O6: 2 | R6: 1 | T6: 2 | U6: 2 | AB6: 1 | AD6: 2
A7: 6 | B7: 45939 | C7: =COUNTIF(D7:AO7,"<>") -> 12 | E7: 2 | G7: 2 | J7: 1 | L7: 1 | M7: 1 | O7: 2 | R7: 2 | S7: 1 | T7: 2 | U7: 1 | AB7: 2 | AD7: 1
A8: 7 | B8: 45939 | C8: =COUNTIF(D8:AO8,"<>") -> 12 | E8: 2 | G8: 2 | J8: 1 | L8: 1 | M8: 1 | O8: 2 | R8: 2 | S8: 1 | T8: 2 | U8: 1 | AB8: 2 | AD8: 1
A9: 8 | B9: 45944 | C9: =COUNTIF(D9:AO9,"<>") -> 12 | D9: 2 | E9: 1 | G9: 2 | H9: 1 | I9: 2 | L9: 2 | N9: 2 | P9: 1 | R9: 1 | S9: 1 | T9: 1 | U9: 2
A10: 9 | B10: 45944 | C10: =COUNTIF(D10:AO10,"<>") -> 12 | D10: 2 | E10: 1 | G10: 2 | H10: 1 | I10: 2 | L10: 2 | N10: 2 | P10: 1 | R10: 1 | S10: 1 | T10: 1 | U10: 2
A11: 10 | B11: 45946 | C11: =COUNTIF(D11:AO11,"<>") -> 8 | E11: 1 | J11: 2 | L11: 1 | M11: 1 | O11: 1 | R11: 2 | T11: 2 | U11: 2
A12: 11 | B12: 45946 | C12: =COUNTIF(D12:AO12,"<>") -> 8 | E12: 1 | J12: 2 | L12: 1 | M12: 1 | O12: 1 | R12: 2 | T12: 2 | U12: 2
A13: 12 | B13: 45951 | C13: =COUNTIF(D13:AO13,"<>") -> 12 | D13: 1 | E13: 1 | G13: 2 | H13: 2 | I13: 2 | J13: 1 | N13: 1 | R13: 1 | S13: 2 | T13: 2 | U13: 2 | W13: 1
A14: 13 | B14: 45951 | C14: =COUNTIF(D14:AO14,"<>") -> 12 | D14: 1 | E14: 1 | G14: 2 | H14: 2 | I14: 2 | J14: 1 | N14: 1 | R14: 1 | S14: 2 | T14: 2 | U14: 2 | W14: 1
A15: 14 | B15: 45953 | C15: =COUNTIF(D15:AO15,"<>") -> 11 | G15: 2 | L15: 1 | M15: 1 | O15: 2 | S15: 1 | T15: 2 | U15: 2 | AA15: 1 | AD15: 2 | AE15: 2 | AF15: 1
A16: 15 | B16: 45953 | C16: =COUNTIF(D16:AO16,"<>") -> 11 | G16: 1 | L16: 2 | M16: 2 | O16: 1 | S16: 2 | T16: 1 | U16: 1 | AA16: 2 | AD16: 1 | AE16: 1 | AF16: 2
A17: 16 | B17: 45958 | C17: =COUNTIF(D17:AO17,"<>") -> 12 | E17: 2 | H17: 1 | I17: 1 | J17: 1 | K17: 2 | N17: 2 | O17: 2 | R17: 1 | S17: 1 | T17: 2 | U17: 2 | W17: 1
A18: 17 | B18: 45958 | C18: =COUNTIF(D18:AO18,"<>") -> 12 | E18: 2 | H18: 1 | I18: 1 | J18: 1 | K18: 2 | N18: 2 | O18: 2 | R18: 1 | S18: 1 | T18: 2 | U18: 2 | W18: 1
A19: 18 | B19: 45960 | C19: =COUNTIF(D19:AO19,"<>") -> 12 | E19: 1 | J19: 2 | M19: 2 | O19: 1 | R19: 1 | S19: 2 | T19: 2 | AA19: 1 | AG19: 1 | AH19: 2 | AI19: 2 | AJ19: 1
A20: 19 | B20: 45960 | C20: =COUNTIF(D20:AY20,"<>") -> 12 | E20: 2 | J20: 1 | M20: 1 | O20: 2 | R20: 2 | S20: 1 | T20: 1 | AA20: 2 | AG20: 2 | AH20: 1 | AI20: 1 | AJ20: 2
A21: 20 | B21: 45965 | C21: =COUNTIF(D21:AY21,"<>") -> 11 | E21: 2 | I21: 1 | K21: 1 | L21: 2 | M21: 2 | O21: 2 | Q21: 2 | R21: 1 | T21: 2 | U21: 1 | W21: 1
A22: 21 | B22: 45965 | C22: =COUNTIF(D22:AY22,"<>") -> 11 | E22: 2 | I22: 1 | K22: 1 | L22: 2 | M22: 2 | O22: 2 | Q22: 2 | R22: 1 | T22: 2 | U22: 1 | W22: 1
A23: 22 | B23: 45967 | C23: =COUNTIF(D23:AY23,"<>") -> 12 | E23: 1 | H23: 2 | I23: 2 | J23: 1 | L23: 1 | M23: 2 | O23: 2 | R23: 1 | S23: 2 | T23: 1 | U23: 2 | AA23: 1
A24: 23 | B24: 45967 | C24: =COUNTIF(D24:AY24,"<>") -> 12 | E24: 1 | H24: 2 | I24: 2 | J24: 1 | L24: 1 | M24: 2 | O24: 2 | R24: 1 | S24: 2 | T24: 1 | U24: 2 | AA24: 1
A25: 24 | B25: 45967 | C25: =COUNTIF(D25:AY25,"<>") -> 12 | E25: 1 | H25: 2 | I25: 2 | J25: 1 | L25: 1 | M25: 2 | O25: 2 | R25: 1 | S25: 2 | T25: 1 | U25: 2 | AA25: 1
A26: 25 | B26: 45972 | C26: =COUNTIF(D26:AY26,"<>") -> 12 | E26: 2 | H26: 1 | I26: 2 | J26: 1 | K26: 1 | L26: 2 | M26: 1 | R26: 1 | S26: 1 | T26: 2 | U26: 2 | W26: 2
A27: 26 | B27: 45972 | C27: =COUNTIF(D27:AY27,"<>") -> 12 | E27: 2 | H27: 1 | I27: 2 | J27: 1 | K27: 1 | L27: 2 | M27: 1 | R27: 1 | S27: 1 | T27: 2 | U27: 2 | W27: 2
A28: 27 | B28: 45972 | C28: =COUNTIF(D28:AY28,"<>") -> 12 | E28: 2 | H28: 1 | I28: 2 | J28: 1 | K28: 1 | L28: 2 | M28: 1 | R28: 1 | S28: 1 | T28: 2 | U28: 2 | W28: 2
A29: 28 | B29: 45974 | C29: =COUNTIF(D29:AY29,"<>") -> 12 | E29: 1 | J29: 2 | L29: 1 | M29: 2 | O29: 2 | R29: 1 | S29: 2 | T29: 1 | U29: 2 | AI29: 2 | AJ29: 1 | AK29: 1
A30: 29 | B30: 45974 | C30: =COUNTIF(D30:AY30,"<>") -> 11 | E30: 1 | J30: 2 | M30: 2 | O30: 2 | R30: 1 | S30: 2 | T30: 1 | U30: 2 | AI30: 2 | AJ30: 1 | AK30: 1
A31: 30 | B31: 45979 | C31: =COUNTIF(D31:AY31,"<>") -> 12 | E31: 2 | H31: 1 | I31: 1 | J31: 1 | K31: 2 | L31: 2 | N31: 2 | Q31: 2 | R31: 1 | T31: 2 | W31: 1 | AG31: 1
A32: 31 | B32: 45979 | C32: =COUNTIF(D32:AY32,"<>") -> 12 | E32: 2 | H32: 1 | I32: 1 | J32: 1 | K32: 2 | L32: 2 | N32: 2 | Q32: 2 | R32: 1 | T32: 2 | W32: 1 | AG32: 1
A33: 32 | B33: 45981 | C33: =COUNTIF(D33:AY33,"<>") -> 9 | E33: 1 | I33: 2 | J33: 1 | L33: 2 | M33: 1 | O33: 2 | R33: 1 | T33: 2 | U33: 2
A34: 33 | B34: 45981 | C34: =COUNTIF(D34:AY34,"<>") -> 9 | E34: 1 | I34: 1 | J34: 1 | L34: 2 | M34: 1 | O34: 2 | R34: 1 | T34: 2 | U34: 2
A35: 34 | B35: 45981 | C35: =COUNTIF(D35:AY35,"<>") -> 9 | E35: 1 | I35: 1 | J35: 1 | L35: 2 | M35: 1 | O35: 2 | R35: 1 | T35: 2 | U35: 2
A36: 35 | B36: 45986 | C36: =COUNTIF(D36:AY36,"<>") -> 12 | H36: 2 | I36: 1 | J36: 2 | K36: 2 | L36: 1 | N36: 2 | O36: 1 | R36: 2 | T36: 2 | U36: 1 | W36: 1 | AG36: 1
A37: 36 | B37: 45986 | C37: =COUNTIF(D37:AY37,"<>") -> 12 | H37: 1 | I37: 2 | J37: 1 | K37: 1 | L37: 2 | N37: 1 | O37: 2 | R37: 1 | T37: 1 | U37: 2 | W37: 2 | AG37: 2
A38: 37 | B38: 45988 | C38: =COUNTIF(D38:AY38,"<>") -> 12 | E38: 1 | I38: 1 | J38: 2 | L38: 1 | M38: 1 | O38: 2 | R38: 2 | T38: 2 | W38: 1 | AB38: 2 | AD38: 2 | AL38: 1
A39: 38 | B39: 45988 | C39: =COUNTIF(D39:AY39,"<>") -> 12 | E39: 1 | I39: 1 | J39: 2 | M39: 1 | O39: 2 | R39: 2 | T39: 2 | W39: 1 | AB39: 2 | AD39: 2 | AL39: 1 | AM39: 1
A40: 39 | B40: 45989 | C40: =COUNTIF(D40:AY40,"<>") -> 12 | E40: 2 | I40: 2 | J40: 1 | M40: 2 | O40: 1 | R40: 1 | T40: 1 | W40: 2 | AB40: 1 | AD40: 1 | AL40: 2 | AM40: 2
...

Sheet Resultados
A1: Campeonato Kostkas 2025-2026
B3: Fecha: | C3: =max(Partidos!B4:B491) -> 46035 | E3: Jugados: | G3: =COUNTIF(Partidos!C2:C502,"<>") -> 62
B5: Jugados | C5: Ganados | D5: Puntos | E5: % | F5: 25%? | G5: Racha | J5: Top Puntos | N5: Top Jugados | R5: Top Eficiencia (25% Partidos) | U5: MVP por mes
A6: Ander | B6: =COUNT(Partidos!D2:D292) -> 4 | C6: =COUNTIF(Partidos!D2:D292,">1") -> 2 | D6: =B6+C6 -> 6 | E6: =IF(C6=0,0,C6/B6) -> 0.5 | F6: =IF(B6>($G$3*0.25),1,0) -> 0 | G6: =IFERROR(__xludf.DUMMYFUNCTION("SUBSTITUTE(SUBSTITUTE(TEXTJOIN("""",TRUE,QUERY(Partidos!$A$2:Partidos!$AY$400,""Select D WHERE D IS NOT NULL Order By A DESC limit 5"")),""1"",""🔴""),""2"",""🟢"")"),"🔴🔴🟢🟢") -> 🔴🔴🟢🟢 | I6: 🥇 | J6: =IFERROR(__xludf.DUMMYFUNCTION("QUERY(A6:E972,""Select D Order By D DESC limit 42"")"),95.0) -> 95 | K6: =IFERROR(__xludf.DUMMYFUNCTION("QUERY(A6:E972,""Select A Order By D DESC, C DESC limit 42"")"),"Txus") -> Txus | M6: 🥇 | N6: =IFERROR(__xludf.DUMMYFUNCTION("QUERY(A6:E972,""Select B Order By B DESC limit 42"")"),60.0) -> 60 | O6: =IFERROR(__xludf.DUMMYFUNCTION("QUERY(A6:E972,""Select A Order By B DESC limit 42"")"),"Txus") -> Txus | Q6: 🥇 | R6: =IFERROR(__xludf.DUMMYFUNCTION("QUERY(A6:F972,""Select E WHERE F>0 Order By E DESC, B ASC limit 42"")"),0.7142857142857143) -> 0.71428571 | S6: =IFERROR(__xludf.DUMMYFUNCTION("QUERY(A6:F972,""Select A WHERE F>0 Order By E DESC, B ASC limit 42"")"),"Miguel T.") -> Miguel T. | U6: Octubre | V6: 🏆 Txus
A7: Aitor Andonegi | B7: =COUNT(Partidos!E2:E293) -> 56 | C7: =COUNTIF(Partidos!E2:E293,">1") -> 24 | D7: =B7+C7 -> 80 | E7: =IF(C7=0,0,C7/B7) -> 0.42857143 | F7: =IF(B7>($G$3*0.25),1,0) -> 1 | G7: =IFERROR(__xludf.DUMMYFUNCTION("SUBSTITUTE(SUBSTITUTE(TEXTJOIN("""",TRUE,QUERY(Partidos!$A$2:Partidos!$AY$400,""Select E WHERE E IS NOT NULL Order By A DESC limit 5"")),""1"",""🔴""),""2"",""🟢"")"),"🔴🔴🔴🔴🟢") -> 🔴🔴🔴🔴🟢 | I7: 🥈 | J7: =IFERROR(__xludf.DUMMYFUNCTION("""COMPUTED_VALUE"""),80.0) -> 80 | K7: =IFERROR(__xludf.DUMMYFUNCTION("""COMPUTED_VALUE"""),"Aitor Andonegi") -> Aitor Andonegi | M7: 🥈 | N7: =IFERROR(__xludf.DUMMYFUNCTION("""COMPUTED_VALUE"""),56.0) -> 56 | O7: =IFERROR(__xludf.DUMMYFUNCTION("""COMPUTED_VALUE"""),"Aitor Andonegi") -> Aitor Andonegi | Q7: 🥈 | R7: =IFERROR(__xludf.DUMMYFUNCTION("""COMPUTED_VALUE"""),0.7142857142857143) -> 0.71428571 | S7: =IFERROR(__xludf.DUMMYFUNCTION("""COMPUTED_VALUE"""),"Unai") -> Unai | U7: Noviembre | V7: 🏆 Txus
A8: Aitor Zuñiga | B8: =COUNT(Partidos!F2:F294) -> 2 | C8: =COUNTIF(Partidos!F2:F294,">1") -> 1 | D8: =B8+C8 -> 3 | E8: =IF(C8=0,0,C8/B8) -> 0.5 | F8: =IF(B8>($G$3*0.25),1,0) -> 0 | G8: =IFERROR(__xludf.DUMMYFUNCTION("SUBSTITUTE(SUBSTITUTE(TEXTJOIN("""",TRUE,QUERY(Partidos!$A$2:Partidos!$AY$400,""Select F WHERE F IS NOT NULL Order By A DESC limit 5"")),""1"",""🔴""),""2"",""🟢"")"),"🔴🟢") -> 🔴🟢 | I8: 🥉 | J8: =IFERROR(__xludf.DUMMYFUNCTION("""COMPUTED_VALUE"""),74.0) -> 74 | K8: =IFERROR(__xludf.DUMMYFUNCTION("""COMPUTED_VALUE"""),"Sixers") -> Sixers | M8: 🥉 | N8: =IFERROR(__xludf.DUMMYFUNCTION("""COMPUTED_VALUE"""),53.0) -> 53 | O8: =IFERROR(__xludf.DUMMYFUNCTION("""COMPUTED_VALUE"""),"Sixers") -> Sixers | Q8: 🥉 | R8: =IFERROR(__xludf.DUMMYFUNCTION("""COMPUTED_VALUE"""),0.6976744186046512) -> 0.69767442 | S8: =IFERROR(__xludf.DUMMYFUNCTION("""COMPUTED_VALUE"""),"Óscar") -> Óscar | U8: Diciembre | V8: 🏆 Txus & Aitor A.
A9: Chocarro | B9: =COUNT(Partidos!G2:G293) -> 13 | C9: =COUNTIF(Partidos!G2:G293,">1") -> 10 | D9: =B9+C9 -> 23 | E9: =IF(C9=0,0,C9/B9) -> 0.76923077 | F9: =IF(B9>($G$3*0.25),1,0) -> 0 | G9: =IFERROR(__xludf.DUMMYFUNCTION("SUBSTITUTE(SUBSTITUTE(TEXTJOIN("""",TRUE,QUERY(Partidos!$A$2:Partidos!$AY$400,""Select G WHERE G IS NOT NULL Order By A DESC limit 5"")),""1"",""🔴""),""2"",""🟢"")"),"🔴🟢🟢🟢🟢") -> 🔴🟢🟢🟢🟢 | J9: =IFERROR(__xludf.DUMMYFUNCTION("""COMPUTED_VALUE"""),73.0) -> 73 | K9: =IFERROR(__xludf.DUMMYFUNCTION("""COMPUTED_VALUE"""),"Óscar") -> Óscar | N9: =IFERROR(__xludf.DUMMYFUNCTION("""COMPUTED_VALUE"""),49.0) -> 49 | O9: =IFERROR(__xludf.DUMMYFUNCTION("""COMPUTED_VALUE"""),"Eddy") -> Eddy | R9: =IFERROR(__xludf.DUMMYFUNCTION("""COMPUTED_VALUE"""),0.6) -> 0.6 | S9: =IFERROR(__xludf.DUMMYFUNCTION("""COMPUTED_VALUE"""),"Jon A.") -> Jon A. | U9: Enero
A10: David Culé | B10: =COUNT(Partidos!H2:H96) -> 31 | C10: =COUNTIF(Partidos!H2:H296,">1") -> 11 | D10: =B10+C10 -> 42 | E10: =IF(C10=0,0,C10/B10) -> 0.35483871 | F10: =IF(B10>($G$3*0.25),1,0) -> 1 | G10: =IFERROR(__xludf.DUMMYFUNCTION("SUBSTITUTE(SUBSTITUTE(TEXTJOIN("""",TRUE,QUERY(Partidos!$A$2:Partidos!$AY$400,""Select H WHERE H IS NOT NULL Order By A DESC limit 5"")),""1"",""🔴""),""2"",""🟢"")"),"🔴🔴🔴🔴🟢") -> 🔴🔴🔴🔴🟢 | J10: =IFERROR(__xludf.DUMMYFUNCTION("""COMPUTED_VALUE"""),72.0) -> 72 | K10: =IFERROR(__xludf.DUMMYFUNCTION("""COMPUTED_VALUE"""),"Unai") -> Unai | N10: =IFERROR(__xludf.DUMMYFUNCTION("""COMPUTED_VALUE"""),44.0) -> 44 | O10: =IFERROR(__xludf.DUMMYFUNCTION("""COMPUTED_VALUE"""),"Iñaki") -> Iñaki | R10: =IFERROR(__xludf.DUMMYFUNCTION("""COMPUTED_VALUE"""),0.5833333333333334) -> 0.58333333 | S10: =IFERROR(__xludf.DUMMYFUNCTION("""COMPUTED_VALUE"""),"Txus") -> Txus | U10: Febrero
A11: David Ras | B11: =COUNT(Partidos!I2:I293) -> 32 | C11: =COUNTIF(Partidos!I2:I293,">1") -> 17 | D11: =B11+C11 -> 49 | E11: =IF(C11=0,0,C11/B11) -> 0.53125 | F11: =IF(B11>($G$3*0.25),1,0) -> 1 | G11: =IFERROR(__xludf.DUMMYFUNCTION("SUBSTITUTE(SUBSTITUTE(TEXTJOIN("""",TRUE,QUERY(Partidos!$A$2:Partidos!$AY$400,""Select I WHERE I IS NOT NULL Order By A DESC limit 5"")),""1"",""🔴""),""2"",""🟢"")"),"🟢🟢🔴🟢🔴") -> 🟢🟢🔴🟢🔴 | J11: =IFERROR(__xludf.DUMMYFUNCTION("""COMPUTED_VALUE"""),69.0) -> 69 | K11: =IFERROR(__xludf.DUMMYFUNCTION("""COMPUTED_VALUE"""),"Eddy") -> Eddy | N11: =IFERROR(__xludf.DUMMYFUNCTION("""COMPUTED_VALUE"""),43.0) -> 43 | O11: =IFERROR(__xludf.DUMMYFUNCTION("""COMPUTED_VALUE"""),"Óscar") -> Óscar | R11: =IFERROR(__xludf.DUMMYFUNCTION("""COMPUTED_VALUE"""),0.5666666666666667) -> 0.56666667 | S11: =IFERROR(__xludf.DUMMYFUNCTION("""COMPUTED_VALUE"""),"Enrique") -> Enrique | U11: Marzo
A12: Eddy | B12: =COUNT(Partidos!J2:J291) -> 49 | C12: =COUNTIF(Partidos!J2:J292,">1") -> 20 | D12: =B12+C12 -> 69 | E12: =IF(C12=0,0,C12/B12) -> 0.40816327 | F12: =IF(B12>($G$3*0.25),1,0) -> 1 | G12: =IFERROR(__xludf.DUMMYFUNCTION("SUBSTITUTE(SUBSTITUTE(TEXTJOIN("""",TRUE,QUERY(Partidos!$A$2:Partidos!$AY$400,""Select J WHERE J IS NOT NULL Order By A DESC limit 5"")),""1"",""🔴""),""2"",""🟢"")"),"🟢🟢🔴🟢🔴") -> 🟢🟢🔴🟢🔴 | J12: =IFERROR(__xludf.DUMMYFUNCTION("""COMPUTED_VALUE"""),62.0) -> 62 | K12: =IFERROR(__xludf.DUMMYFUNCTION("""COMPUTED_VALUE"""),"Iñaki") -> Iñaki | N12: =IFERROR(__xludf.DUMMYFUNCTION("""COMPUTED_VALUE"""),42.0) -> 42 | O12: =IFERROR(__xludf.DUMMYFUNCTION("""COMPUTED_VALUE"""),"Unai") -> Unai | R12: =IFERROR(__xludf.DUMMYFUNCTION("""COMPUTED_VALUE"""),0.53125) -> 0.53125 | S12: =IFERROR(__xludf.DUMMYFUNCTION("""COMPUTED_VALUE"""),"David Ras") -> David Ras | U12: Abril
A13: Enrique | B13: =COUNT(Partidos!K2:K292) -> 30 | C13: =COUNTIF(Partidos!K3:K293,">1") -> 17 | D13: =B13+C13 -> 47 | E13: =IF(C13=0,0,C13/B13) -> 0.56666667 | F13: =IF(B13>($G$3*0.25),1,0) -> 1 | G13: =IFERROR(__xludf.DUMMYFUNCTION("SUBSTITUTE(SUBSTITUTE(TEXTJOIN("""",TRUE,QUERY(Partidos!$A$2:Partidos!$AY$400,""Select K WHERE K IS NOT NULL Order By A DESC limit 5"")),""1"",""🔴""),""2"",""🟢"")"),"🔴🔴🟢🟢🟢") -> 🔴🔴🟢🟢🟢 | J13: =IFERROR(__xludf.DUMMYFUNCTION("""COMPUTED_VALUE"""),57.0) -> 57 | K13: =IFERROR(__xludf.DUMMYFUNCTION("""COMPUTED_VALUE"""),"Telmo") -> Telmo | N13: =IFERROR(__xludf.DUMMYFUNCTION("""COMPUTED_VALUE"""),41.0) -> 41 | O13: =IFERROR(__xludf.DUMMYFUNCTION("""COMPUTED_VALUE"""),"Telmo") -> Telmo | R13: =IFERROR(__xludf.DUMMYFUNCTION("""COMPUTED_VALUE"""),0.5) -> 0.5 | S13: =IFERROR(__xludf.DUMMYFUNCTION("""COMPUTED_VALUE"""),"Fer") -> Fer | U13: Mayo
A14: Fer | B14: =COUNT(Partidos!L2:L292) -> 34 | C14: =COUNTIF(Partidos!L2:L291,">1") -> 17 | D14: =B14+C14 -> 51 | E14: =IF(C14=0,0,C14/B14) -> 0.5 | F14: =IF(B14>($G$3*0.25),1,0) -> 1 | G14: =IFERROR(__xludf.DUMMYFUNCTION("SUBSTITUTE(SUBSTITUTE(TEXTJOIN("""",TRUE,QUERY(Partidos!$A$2:Partidos!$AY$400,""Select L WHERE L IS NOT NULL Order By A DESC limit 5"")),""1"",""🔴""),""2"",""🟢"")"),"🔴🔴🟢🔴🔴") -> 🔴🔴🟢🔴🔴 | J14: =IFERROR(__xludf.DUMMYFUNCTION("""COMPUTED_VALUE"""),51.0) -> 51 | K14: =IFERROR(__xludf.DUMMYFUNCTION("""COMPUTED_VALUE"""),"Fer") -> Fer | N14: =IFERROR(__xludf.DUMMYFUNCTION("""COMPUTED_VALUE"""),34.0) -> 34 | O14: =IFERROR(__xludf.DUMMYFUNCTION("""COMPUTED_VALUE"""),"Fer") -> Fer | R14: =IFERROR(__xludf.DUMMYFUNCTION("""COMPUTED_VALUE"""),0.42857142857142855) -> 0.42857143 | S14: =IFERROR(__xludf.DUMMYFUNCTION("""COMPUTED_VALUE"""),"Aitor Andonegi") -> Aitor Andonegi | U14: Junio
A15: Iñaki | B15: =COUNT(Partidos!M2:M292) -> 44 | C15: =COUNTIF(Partidos!M2:M291,">1") -> 18 | D15: =B15+C15 -> 62 | E15: =IF(C15=0,0,C15/B15) -> 0.40909091 | F15: =IF(B15>($G$3*0.25),1,0) -> 1 | G15: =IFERROR(__xludf.DUMMYFUNCTION("SUBSTITUTE(SUBSTITUTE(TEXTJOIN("""",TRUE,QUERY(Partidos!$A$2:Partidos!$AY$400,""Select M WHERE M IS NOT NULL Order By A DESC limit 5"")),""1"",""🔴""),""2"",""🟢"")"),"🟢🟢🔴🔴🔴") -> 🟢🟢🔴🔴🔴 | J15: =IFERROR(__xludf.DUMMYFUNCTION("""COMPUTED_VALUE"""),49.0) -> 49 | K15: =IFERROR(__xludf.DUMMYFUNCTION("""COMPUTED_VALUE"""),"David Ras") -> David Ras | N15: =IFERROR(__xludf.DUMMYFUNCTION("""COMPUTED_VALUE"""),32.0) -> 32 | O15: =IFERROR(__xludf.DUMMYFUNCTION("""COMPUTED_VALUE"""),"David Ras") -> David Ras | R15: =IFERROR(__xludf.DUMMYFUNCTION("""COMPUTED_VALUE"""),0.4090909090909091) -> 0.40909091 | S15: =IFERROR(__xludf.DUMMYFUNCTION("""COMPUTED_VALUE"""),"Iñaki") -> Iñaki | U15: Julio
A16: Miguel T. | B16: =COUNT(Partidos!N2:N293) -> 21 | C16: =COUNTIF(Partidos!N2:N292,">1") -> 15 | D16: =B16+C16 -> 36 | E16: =IF(C16=0,0,C16/B16) -> 0.71428571 | F16: =IF(B16>($G$3*0.25),1,0) -> 1 | G16: =IFERROR(__xludf.DUMMYFUNCTION("SUBSTITUTE(SUBSTITUTE(TEXTJOIN("""",TRUE,QUERY(Partidos!$A$2:Partidos!$AY$400,""Select N WHERE N IS NOT NULL Order By A DESC limit 5"")),""1"",""🔴""),""2"",""🟢"")"),"🟢🟢🟢🟢🟢") -> 🟢🟢🟢🟢🟢 | J16: =IFERROR(__xludf.DUMMYFUNCTION("""COMPUTED_VALUE"""),47.0) -> 47 | K16: =IFERROR(__xludf.DUMMYFUNCTION("""COMPUTED_VALUE"""),"Enrique") -> Enrique | N16: =IFERROR(__xludf.DUMMYFUNCTION("""COMPUTED_VALUE"""),31.0) -> 31 | O16: =IFERROR(__xludf.DUMMYFUNCTION("""COMPUTED_VALUE"""),"David Culé") -> David Culé | R16: =IFERROR(__xludf.DUMMYFUNCTION("""COMPUTED_VALUE"""),0.40816326530612246) -> 0.40816327 | S16: =IFERROR(__xludf.DUMMYFUNCTION("""COMPUTED_VALUE"""),"Eddy") -> Eddy
A17: Óscar | B17: =COUNT(Partidos!O2:O293) -> 43 | C17: =COUNTIF(Partidos!O2:O293,">1") -> 30 | D17: =B17+C17 -> 73 | E17: =IF(C17=0,0,C17/B17) -> 0.69767442 | F17: =IF(B17>($G$3*0.25),1,0) -> 1 | G17: =IFERROR(__xludf.DUMMYFUNCTION("SUBSTITUTE(SUBSTITUTE(TEXTJOIN("""",TRUE,QUERY(Partidos!$A$2:Partidos!$AY$400,""Select O WHERE O IS NOT NULL Order By A DESC limit 5"")),""1"",""🔴""),""2"",""🟢"")"),"🟢🟢🟢🟢🟢") -> 🟢🟢🟢🟢🟢 | J17: =IFERROR(__xludf.DUMMYFUNCTION("""COMPUTED_VALUE"""),42.0) -> 42 | K17: =IFERROR(__xludf.DUMMYFUNCTION("""COMPUTED_VALUE"""),"David Culé") -> David Culé | N17: =IFERROR(__xludf.DUMMYFUNCTION("""COMPUTED_VALUE"""),30.0) -> 30 | O17: =IFERROR(__xludf.DUMMYFUNCTION("""COMPUTED_VALUE"""),"Enrique") -> Enrique | R17: =IFERROR(__xludf.DUMMYFUNCTION("""COMPUTED_VALUE"""),0.39622641509433965) -> 0.39622642 | S17: =IFERROR(__xludf.DUMMYFUNCTION("""COMPUTED_VALUE"""),"Sixers") -> Sixers
A18: Raúl | B18: =COUNT(Partidos!P2:P293) -> 11 | C18: =COUNTIF(Partidos!P2:P293,">1") -> 4 | D18: =B18+C18 -> 15 | E18: =IF(C18=0,0,C18/B18) -> 0.36363636 | F18: =IF(B18>($G$3*0.25),1,0) -> 0 | G18: =IFERROR(__xludf.DUMMYFUNCTION("SUBSTITUTE(SUBSTITUTE(TEXTJOIN("""",TRUE,QUERY(Partidos!$A$2:Partidos!$AY$400,""Select P WHERE P IS NOT NULL Order By A DESC limit 5"")),""1"",""🔴""),""2"",""🟢"")"),"🟢🟢🔴🟢🔴") -> 🟢🟢🔴🟢🔴 | J18: =IFERROR(__xludf.DUMMYFUNCTION("""COMPUTED_VALUE"""),36.0) -> 36 | K18: =IFERROR(__xludf.DUMMYFUNCTION("""COMPUTED_VALUE"""),"Miguel T.") -> Miguel T. | N18: =IFERROR(__xludf.DUMMYFUNCTION("""COMPUTED_VALUE"""),27.0) -> 27 | O18: =IFERROR(__xludf.DUMMYFUNCTION("""COMPUTED_VALUE"""),"Zapas") -> Zapas | R18: =IFERROR(__xludf.DUMMYFUNCTION("""COMPUTED_VALUE"""),0.3902439024390244) -> 0.3902439 | S18: =IFERROR(__xludf.DUMMYFUNCTION("""COMPUTED_VALUE"""),"Telmo") -> Telmo
A19: Ritxo | B19: =COUNT(Partidos!Q2:Q293) -> 4 | C19: =COUNTIF(Partidos!Q2:Q293,">1") -> 4 | D19: =B19+C19 -> 8 | E19: =IF(C19=0,0,C19/B19) -> 1 | F19: =IF(B19>($G$3*0.25),1,0) -> 0 | G19: =IFERROR(__xludf.DUMMYFUNCTION("SUBSTITUTE(SUBSTITUTE(TEXTJOIN("""",TRUE,QUERY(Partidos!$A$2:Partidos!$AY$400,""Select Q WHERE Q IS NOT NULL Order By A DESC limit 5"")),""1"",""🔴""),""2"",""🟢"")"),"🟢🟢🟢🟢") -> 🟢🟢🟢🟢 | J19: =IFERROR(__xludf.DUMMYFUNCTION("""COMPUTED_VALUE"""),34.0) -> 34 | K19: =IFERROR(__xludf.DUMMYFUNCTION("""COMPUTED_VALUE"""),"Zapas") -> Zapas | N19: =IFERROR(__xludf.DUMMYFUNCTION("""COMPUTED_VALUE"""),21.0) -> 21 | O19: =IFERROR(__xludf.DUMMYFUNCTION("""COMPUTED_VALUE"""),"Miguel T.") -> Miguel T. | R19: =IFERROR(__xludf.DUMMYFUNCTION("""COMPUTED_VALUE"""),0.3684210526315789) -> 0.36842105 | S19: =IFERROR(__xludf.DUMMYFUNCTION("""COMPUTED_VALUE"""),"Iker") -> Iker
A20: Sixers | B20: =COUNT(Partidos!R2:R293) -> 53 | C20: =COUNTIF(Partidos!R2:R294,">1") -> 21 | D20: =B20+C20 -> 74 | E20: =IF(C20=0,0,C20/B20) -> 0.39622642 | F20: =IF(B20>($G$3*0.25),1,0) -> 1 | G20: =IFERROR(__xludf.DUMMYFUNCTION("SUBSTITUTE(SUBSTITUTE(TEXTJOIN("""",TRUE,QUERY(Partidos!$A$2:Partidos!$AY$400,""Select R WHERE R IS NOT NULL Order By A DESC limit 5"")),""1"",""🔴""),""2"",""🟢"")"),"🟢🟢🟢🟢🔴") -> 🟢🟢🟢🟢🔴 | J20: =IFERROR(__xludf.DUMMYFUNCTION("""COMPUTED_VALUE"""),32.0) -> 32 | K20: =IFERROR(__xludf.DUMMYFUNCTION("""COMPUTED_VALUE"""),"Jon A.") -> Jon A. | N20: =IFERROR(__xludf.DUMMYFUNCTION("""COMPUTED_VALUE"""),20.0) -> 20 | O20: =IFERROR(__xludf.DUMMYFUNCTION("""COMPUTED_VALUE"""),"Jon A.") -> Jon A. | R20: =IFERROR(__xludf.DUMMYFUNCTION("""COMPUTED_VALUE"""),0.3548387096774194) -> 0.35483871 | S20: =IFERROR(__xludf.DUMMYFUNCTION("""COMPUTED_VALUE"""),"David Culé") -> David Culé
A21: Telmo | B21: =COUNT(Partidos!S2:S293) -> 41 | C21: =COUNTIF(Partidos!S2:S292,">1") -> 16 | D21: =B21+C21 -> 57 | E21: =IF(C21=0,0,C21/B21) -> 0.3902439 | F21: =IF(B21>($G$3*0.25),1,0) -> 1 | G21: =IFERROR(__xludf.DUMMYFUNCTION("SUBSTITUTE(SUBSTITUTE(TEXTJOIN("""",TRUE,QUERY(Partidos!$A$2:Partidos!$AY$400,""Select S WHERE S IS NOT NULL Order By A DESC limit 5"")),""1"",""🔴""),""2"",""🟢"")"),"🔴🔴🔴🔴🔴") -> 🔴🔴🔴🔴🔴 | J21: =IFERROR(__xludf.DUMMYFUNCTION("""COMPUTED_VALUE"""),26.0) -> 26 | K21: =IFERROR(__xludf.DUMMYFUNCTION("""COMPUTED_VALUE"""),"Iker") -> Iker | N21: =IFERROR(__xludf.DUMMYFUNCTION("""COMPUTED_VALUE"""),19.0) -> 19 | O21: =IFERROR(__xludf.DUMMYFUNCTION("""COMPUTED_VALUE"""),"Iker") -> Iker | R21: =IFERROR(__xludf.DUMMYFUNCTION("""COMPUTED_VALUE"""),0.25925925925925924) -> 0.25925926 | S21: =IFERROR(__xludf.DUMMYFUNCTION("""COMPUTED_VALUE"""),"Zapas") -> Zapas
A22: Txus | B22: =COUNT(Partidos!T2:T292) -> 60 | C22: =COUNTIF(Partidos!T2:T292,">1") -> 35 | D22: =B22+C22 -> 95 | E22: =IF(C22=0,0,C22/B22) -> 0.58333333 | F22: =IF(B22>($G$3*0.25),1,0) -> 1 | G22: =IFERROR(__xludf.DUMMYFUNCTION("SUBSTITUTE(SUBSTITUTE(TEXTJOIN("""",TRUE,QUERY(Partidos!$A$2:Partidos!$AY$400,""Select T WHERE T IS NOT NULL Order By A DESC limit 5"")),""1"",""🔴""),""2"",""🟢"")"),"🟢🟢🔴🔴🔴") -> 🟢🟢🔴🔴🔴 | J22: =IFERROR(__xludf.DUMMYFUNCTION("""COMPUTED_VALUE"""),23.0) -> 23 | K22: =IFERROR(__xludf.DUMMYFUNCTION("""COMPUTED_VALUE"""),"Chocarro") -> Chocarro | N22: =IFERROR(__xludf.DUMMYFUNCTION("""COMPUTED_VALUE"""),13.0) -> 13 | O22: =IFERROR(__xludf.DUMMYFUNCTION("""COMPUTED_VALUE"""),"Chocarro") -> Chocarro
A23: Unai | B23: =COUNT(Partidos!U2:U293) -> 42 | C23: =COUNTIF(Partidos!U2:U293,">1") -> 30 | D23: =B23+C23 -> 72 | E23: =IF(C23=0,0,C23/B23) -> 0.71428571 | F23: =IF(B23>($G$3*0.25),1,0) -> 1 | G23: =IFERROR(__xludf.DUMMYFUNCTION("SUBSTITUTE(SUBSTITUTE(TEXTJOIN("""",TRUE,QUERY(Partidos!$A$2:Partidos!$AY$400,""Select U WHERE U IS NOT NULL Order By A DESC limit 5"")),""1"",""🔴""),""2"",""🟢"")"),"🟢🟢🔴🔴🟢") -> 🟢🟢🔴🔴🟢 | J23: =IFERROR(__xludf.DUMMYFUNCTION("""COMPUTED_VALUE"""),17.0) -> 17 | K23: =IFERROR(__xludf.DUMMYFUNCTION("""COMPUTED_VALUE"""),"Lander") -> Lander | N23: =IFERROR(__xludf.DUMMYFUNCTION("""COMPUTED_VALUE"""),11.0) -> 11 | O23: =IFERROR(__xludf.DUMMYFUNCTION("""COMPUTED_VALUE"""),"Raúl") -> Raúl
A24: Xabi | B24: =COUNT(Partidos!V2:V293) -> 0 | C24: =COUNTIF(Partidos!V2:V293,">1") -> 0 | D24: =B24+C24 -> 0 | E24: =IF(C24=0,0,C24/B24) -> 0 | F24: =IF(B24>($G$3*0.25),1,0) -> 0 | G24: =IFERROR(__xludf.DUMMYFUNCTION("SUBSTITUTE(SUBSTITUTE(TEXTJOIN("""",TRUE,QUERY(Partidos!$A$2:Partidos!$AY$400,""Select V WHERE V IS NOT NULL Order By A DESC limit 5"")),""1"",""🔴""),""2"",""🟢"")"),"#N/A") -> #N/A | J24: =IFERROR(__xludf.DUMMYFUNCTION("""COMPUTED_VALUE"""),15.0) -> 15 | K24: =IFERROR(__xludf.DUMMYFUNCTION("""COMPUTED_VALUE"""),"Raúl") -> Raúl | N24: =IFERROR(__xludf.DUMMYFUNCTION("""COMPUTED_VALUE"""),11.0) -> 11 | O24: =IFERROR(__xludf.DUMMYFUNCTION("""COMPUTED_VALUE"""),"Lander") -> Lander
A25: Zapas | B25: =COUNT(Partidos!W2:W2294) -> 27 | C25: =COUNTIF(Partidos!W2:W294,">1") -> 7 | D25: =B25+C25 -> 34 | E25: =IF(C25=0,0,C25/B25) -> 0.25925926 | F25: =IF(B25>($G$3*0.25),1,0) -> 1 | G25: =IFERROR(__xludf.DUMMYFUNCTION("SUBSTITUTE(SUBSTITUTE(TEXTJOIN("""",TRUE,QUERY(Partidos!$A$2:Partidos!$AY$400,""Select W WHERE W IS NOT NULL Order By A DESC limit 5"")),""1"",""🔴""),""2"",""🟢"")"),"🔴🔴🔴🔴🔴") -> 🔴🔴🔴🔴🔴 | J25: =IFERROR(__xludf.DUMMYFUNCTION("""COMPUTED_VALUE"""),14.0) -> 14 | K25: =IFERROR(__xludf.DUMMYFUNCTION("""COMPUTED_VALUE"""),"David Arg.") -> David Arg. | N25: =IFERROR(__xludf.DUMMYFUNCTION("""COMPUTED_VALUE"""),8.0) -> 8 | O25: =IFERROR(__xludf.DUMMYFUNCTION("""COMPUTED_VALUE"""),"David Arg.") -> David Arg.
A26: Borja | B26: =COUNT(Partidos!Y2:Y292) -> 5 | C26: =COUNTIF(Partidos!Y2:Y292,">1") -> 4 | D26: =B26+C26 -> 9 | E26: =IF(C26=0,0,C26/B26) -> 0.8 | F26: =IF(B26>($G$3*0.25),1,0) -> 0 | G26: =IFERROR(__xludf.DUMMYFUNCTION("SUBSTITUTE(SUBSTITUTE(TEXTJOIN("""",TRUE,QUERY(Partidos!$A$2:Partidos!$AY$400,""Select Y WHERE Y IS NOT NULL Order By A DESC limit 5"")),""1"",""🔴""),""2"",""🟢"")"),"🟢🟢🟢🔴🟢") -> 🟢🟢🟢🔴🟢 | J26: =IFERROR(__xludf.DUMMYFUNCTION("""COMPUTED_VALUE"""),9.0) -> 9 | K26: =IFERROR(__xludf.DUMMYFUNCTION("""COMPUTED_VALUE"""),"Borja") -> Borja | N26: =IFERROR(__xludf.DUMMYFUNCTION("""COMPUTED_VALUE"""),7.0) -> 7 | O26: =IFERROR(__xludf.DUMMYFUNCTION("""COMPUTED_VALUE"""),"Jesús") -> Jesús
A27: Hidalgo | B27: =COUNT(Partidos!Z2:Z293) -> 0 | C27: =COUNTIF(Partidos!Z2:Z293,">1") -> 0 | D27: =B27+C27 -> 0 | E27: =IF(C27=0,0,C27/B27) -> 0 | F27: =IF(B27>($G$3*0.25),1,0) -> 0 | G27: =IFERROR(__xludf.DUMMYFUNCTION("SUBSTITUTE(SUBSTITUTE(TEXTJOIN("""",TRUE,QUERY(Partidos!$A$2:Partidos!$AY$400,""Select Z WHERE Z IS NOT NULL Order By A DESC limit 5"")),""1"",""🔴""),""2"",""🟢"")"),"#N/A") -> #N/A | J27: =IFERROR(__xludf.DUMMYFUNCTION("""COMPUTED_VALUE"""),9.0) -> 9 | K27: =IFERROR(__xludf.DUMMYFUNCTION("""COMPUTED_VALUE"""),"Laura") -> Laura | N27: =IFERROR(__xludf.DUMMYFUNCTION("""COMPUTED_VALUE"""),6.0) -> 6 | O27: =IFERROR(__xludf.DUMMYFUNCTION("""COMPUTED_VALUE"""),"Laura") -> Laura
A28: Jesús | B28: =COUNT(Partidos!AA2:AA294) -> 7 | C28: =COUNTIF(Partidos!AA2:AA294,">1") -> 2 | D28: =B28+C28 -> 9 | E28: =IF(C28=0,0,C28/B28) -> 0.28571429 | F28: =IF(B28>($G$3*0.25),1,0) -> 0 | G28: =IFERROR(__xludf.DUMMYFUNCTION("SUBSTITUTE(SUBSTITUTE(TEXTJOIN("""",TRUE,QUERY(Partidos!$A$2:Partidos!$AY$400,""Select AA WHERE AA IS NOT NULL Order By A DESC limit 5"")),""1"",""🔴""),""2"",""🟢"")"),"🔴🔴🔴🟢🔴") -> 🔴🔴🔴🟢🔴 | J28: =IFERROR(__xludf.DUMMYFUNCTION("""COMPUTED_VALUE"""),9.0) -> 9 | K28: =IFERROR(__xludf.DUMMYFUNCTION("""COMPUTED_VALUE"""),"Jesús") -> Jesús | N28: =IFERROR(__xludf.DUMMYFUNCTION("""COMPUTED_VALUE"""),5.0) -> 5 | O28: =IFERROR(__xludf.DUMMYFUNCTION("""COMPUTED_VALUE"""),"Borja") -> Borja
A29: Jon A. | B29: =COUNT(Partidos!AB2:AB292) -> 20 | C29: =COUNTIF(Partidos!AB2:AB292,">1") -> 12 | D29: =B29+C29 -> 32 | E29: =IF(C29=0,0,C29/B29) -> 0.6 | F29: =IF(B29>($G$3*0.25),1,0) -> 1 | G29: =IFERROR(__xludf.DUMMYFUNCTION("SUBSTITUTE(SUBSTITUTE(TEXTJOIN("""",TRUE,QUERY(Partidos!$A$2:Partidos!$AY$400,""Select AB WHERE AB IS NOT NULL Order By A DESC limit 5"")),""1"",""🔴""),""2"",""🟢"")"),"🔴🔴🟢🟢🔴") -> 🔴🔴🟢🟢🔴 | J29: =IFERROR(__xludf.DUMMYFUNCTION("""COMPUTED_VALUE"""),8.0) -> 8 | K29: =IFERROR(__xludf.DUMMYFUNCTION("""COMPUTED_VALUE"""),"Ritxo") -> Ritxo | N29: =IFERROR(__xludf.DUMMYFUNCTION("""COMPUTED_VALUE"""),4.0) -> 4 | O29: =IFERROR(__xludf.DUMMYFUNCTION("""COMPUTED_VALUE"""),"Ander") -> Ander
A30: Ricky | B30: =COUNT(Partidos!AC2:AC292) -> 0 | C30: =COUNTIF(Partidos!AC2:AC292,">1") -> 0 | D30: =B30+C30 -> 0 | E30: =IF(C30=0,0,C30/B30) -> 0 | F30: =IF(B30>($G$3*0.25),1,0) -> 0 | G30: =IFERROR(__xludf.DUMMYFUNCTION("SUBSTITUTE(SUBSTITUTE(TEXTJOIN("""",TRUE,QUERY(Partidos!$A$2:Partidos!$AY$400,""Select AC WHERE AC IS NOT NULL Order By A DESC limit 5"")),""1"",""🔴""),""2"",""🟢"")"),"#N/A") -> #N/A | J30: =IFERROR(__xludf.DUMMYFUNCTION("""COMPUTED_VALUE"""),7.0) -> 7 | K30: =IFERROR(__xludf.DUMMYFUNCTION("""COMPUTED_VALUE"""),"Moha BK") -> Moha BK | N30: =IFERROR(__xludf.DUMMYFUNCTION("""COMPUTED_VALUE"""),4.0) -> 4 | O30: =IFERROR(__xludf.DUMMYFUNCTION("""COMPUTED_VALUE"""),"Ritxo") -> Ritxo
A31: Iker | B31: =COUNT(Partidos!AD2:AD293) -> 19 | C31: =COUNTIF(Partidos!AD3:AD293,">1") -> 7 | D31: =B31+C31 -> 26 | E31: =IF(C31=0,0,C31/B31) -> 0.36842105 | F31: =IF(B31>($G$3*0.25),1,0) -> 1 | G31: =IFERROR(__xludf.DUMMYFUNCTION("SUBSTITUTE(SUBSTITUTE(TEXTJOIN("""",TRUE,QUERY(Partidos!$A$2:Partidos!$AY$400,""Select AD WHERE AD IS NOT NULL Order By A DESC limit 5"")),""1"",""🔴""),""2"",""🟢"")"),"🔴🔴🔴🔴🟢") -> 🔴🔴🔴🔴🟢 | J31: =IFERROR(__xludf.DUMMYFUNCTION("""COMPUTED_VALUE"""),7.0) -> 7 | K31: =IFERROR(__xludf.DUMMYFUNCTION("""COMPUTED_VALUE"""),"Íñigo") -> Íñigo | N31: =IFERROR(__xludf.DUMMYFUNCTION("""COMPUTED_VALUE"""),4.0) -> 4 | O31: =IFERROR(__xludf.DUMMYFUNCTION("""COMPUTED_VALUE"""),"Javi BK") -> Javi BK
A32: Xabi BK | B32: =COUNT(Partidos!AE2:AE293) -> 2 | C32: =COUNTIF(Partidos!AE2:AE293,">1") -> 1 | D32: =B32+C32 -> 3 | E32: =IF(C32=0,0,C32/B32) -> 0.5 | F32: =IF(B32>($G$3*0.25),1,0) -> 0 | G32: =IFERROR(__xludf.DUMMYFUNCTION("SUBSTITUTE(SUBSTITUTE(TEXTJOIN("""",TRUE,QUERY(Partidos!$A$2:Partidos!$AY$400,""Select AE WHERE AE IS NOT NULL Order By A DESC limit 5"")),""1"",""🔴""),""2"",""🟢"")"),"🔴🟢") -> 🔴🟢 | J32: =IFERROR(__xludf.DUMMYFUNCTION("""COMPUTED_VALUE"""),6.0) -> 6 | K32: =IFERROR(__xludf.DUMMYFUNCTION("""COMPUTED_VALUE"""),"Ander") -> Ander | N32: =IFERROR(__xludf.DUMMYFUNCTION("""COMPUTED_VALUE"""),4.0) -> 4 | O32: =IFERROR(__xludf.DUMMYFUNCTION("""COMPUTED_VALUE"""),"Moha BK") -> Moha BK
A33: Pablo BK | B33: =COUNT(Partidos!AF2:AF294) -> 2 | C33: =COUNTIF(Partidos!AF2:AF294,">1") -> 1 | D33: =B33+C33 -> 3 | E33: =IF(C33=0,0,C33/B33) -> 0.5 | F33: =IF(B33>($G$3*0.25),1,0) -> 0 | G33: =IFERROR(__xludf.DUMMYFUNCTION("SUBSTITUTE(SUBSTITUTE(TEXTJOIN("""",TRUE,QUERY(Partidos!$A$2:Partidos!$AY$400,""Select AF WHERE AF IS NOT NULL Order By A DESC limit 5"")),""1"",""🔴""),""2"",""🟢"")"),"🟢🔴") -> 🟢🔴 | J33: =IFERROR(__xludf.DUMMYFUNCTION("""COMPUTED_VALUE"""),6.0) -> 6 | K33: =IFERROR(__xludf.DUMMYFUNCTION("""COMPUTED_VALUE"""),"Javi BK") -> Javi BK | N33: =IFERROR(__xludf.DUMMYFUNCTION("""COMPUTED_VALUE"""),4.0) -> 4 | O33: =IFERROR(__xludf.DUMMYFUNCTION("""COMPUTED_VALUE"""),"Jonathan BK") -> Jonathan BK
A34: Lander | B34: =COUNT(Partidos!AG2:AG294) -> 11 | C34: =COUNTIF(Partidos!AG2:AG294,">1") -> 6 | D34: =B34+C34 -> 17 | E34: =IF(C34=0,0,C34/B34) -> 0.54545455 | F34: =IF(B34>($G$3*0.25),1,0) -> 0 | G34: =IFERROR(__xludf.DUMMYFUNCTION("SUBSTITUTE(SUBSTITUTE(TEXTJOIN("""",TRUE,QUERY(Partidos!$A$2:Partidos!$AY$400,""Select AG WHERE AG IS NOT NULL Order By A DESC limit 5"")),""1"",""🔴""),""2"",""🟢"")"),"🟢🟢🔴🟢🟢") -> 🟢🟢🔴🟢🟢 | J34: =IFERROR(__xludf.DUMMYFUNCTION("""COMPUTED_VALUE"""),5.0) -> 5 | K34: =IFERROR(__xludf.DUMMYFUNCTION("""COMPUTED_VALUE"""),"Minde") -> Minde | N34: =IFERROR(__xludf.DUMMYFUNCTION("""COMPUTED_VALUE"""),4.0) -> 4 | O34: =IFERROR(__xludf.DUMMYFUNCTION("""COMPUTED_VALUE"""),"Íñigo") -> Íñigo
A35: Javi BK | B35: =COUNT(Partidos!AH2:AH294) -> 4 | C35: =COUNTIF(Partidos!AH2:AH294,">1") -> 2 | D35: =B35+C35 -> 6 | E35: =IF(C35=0,0,C35/B35) -> 0.5 | F35: =IF(B35>($G$3*0.25),1,0) -> 0 | G35: =IFERROR(__xludf.DUMMYFUNCTION("SUBSTITUTE(SUBSTITUTE(TEXTJOIN("""",TRUE,QUERY(Partidos!$A$2:Partidos!$AY$400,""Select AH WHERE AH IS NOT NULL Order By A DESC limit 5"")),""1"",""🔴""),""2"",""🟢"")"),"🔴🟢🔴🟢") -> 🔴🟢🔴🟢 | J35: =IFERROR(__xludf.DUMMYFUNCTION("""COMPUTED_VALUE"""),5.0) -> 5 | K35: =IFERROR(__xludf.DUMMYFUNCTION("""COMPUTED_VALUE"""),"Jonathan BK") -> Jonathan BK | N35: =IFERROR(__xludf.DUMMYFUNCTION("""COMPUTED_VALUE"""),3.0) -> 3 | O35: =IFERROR(__xludf.DUMMYFUNCTION("""COMPUTED_VALUE"""),"Minde") -> Minde
A36: Moha BK | B36: =COUNT(Partidos!AI2:AI294) -> 4 | C36: =COUNTIF(Partidos!AI2:AI294,">1") -> 3 | D36: =B36+C36 -> 7 | E36: =IF(C36=0,0,C36/B36) -> 0.75 | F36: =IF(B36>($G$3*0.25),1,0) -> 0 | G36: =IFERROR(__xludf.DUMMYFUNCTION("SUBSTITUTE(SUBSTITUTE(TEXTJOIN("""",TRUE,QUERY(Partidos!$A$2:Partidos!$AY$400,""Select AI WHERE AI IS NOT NULL Order By A DESC limit 5"")),""1"",""🔴""),""2"",""🟢"")"),"🟢🟢🔴🟢") -> 🟢🟢🔴🟢 | J36: =IFERROR(__xludf.DUMMYFUNCTION("""COMPUTED_VALUE"""),4.0) -> 4 | K36: =IFERROR(__xludf.DUMMYFUNCTION("""COMPUTED_VALUE"""),"Korta") -> Korta | N36: =IFERROR(__xludf.DUMMYFUNCTION("""COMPUTED_VALUE"""),2.0) -> 2 | O36: =IFERROR(__xludf.DUMMYFUNCTION("""COMPUTED_VALUE"""),"Aitor Zuñiga") -> Aitor Zuñiga
A37: Jonathan BK | B37: =COUNT(Partidos!AJ2:AJ294) -> 4 | C37: =COUNTIF(Partidos!AJ2:AJ294,">1") -> 1 | D37: =B37+C37 -> 5 | E37: =IF(C37=0,0,C37/B37) -> 0.25 | F37: =IF(B37>($G$3*0.25),1,0) -> 0 | G37: =IFERROR(__xludf.DUMMYFUNCTION("SUBSTITUTE(SUBSTITUTE(TEXTJOIN("""",TRUE,QUERY(Partidos!$A$2:Partidos!$AY$400,""Select AJ WHERE AJ IS NOT NULL Order By A DESC limit 5"")),""1"",""🔴""),""2"",""🟢"")"),"🔴🔴🟢🔴") -> 🔴🔴🟢🔴 | J37: =IFERROR(__xludf.DUMMYFUNCTION("""COMPUTED_VALUE"""),3.0) -> 3 | K37: =IFERROR(__xludf.DUMMYFUNCTION("""COMPUTED_VALUE"""),"Aitor Zuñiga") -> Aitor Zuñiga | N37: =IFERROR(__xludf.DUMMYFUNCTION("""COMPUTED_VALUE"""),2.0) -> 2 | O37: =IFERROR(__xludf.DUMMYFUNCTION("""COMPUTED_VALUE"""),"Xabi BK") -> Xabi BK
A38: Gio BK | B38: =COUNT(Partidos!AK2:AK294) -> 2 | C38: =COUNTIF(Partidos!AK2:AK294,">1") -> 0 | D38: =B38+C38 -> 2 | E38: =IF(C38=0,0,C38/B38) -> 0 | F38: =IF(B38>($G$3*0.25),1,0) -> 0 | G38: =IFERROR(__xludf.DUMMYFUNCTION("SUBSTITUTE(SUBSTITUTE(TEXTJOIN("""",TRUE,QUERY(Partidos!$A$2:Partidos!$AY$400,""Select AK WHERE AK IS NOT NULL Order By A DESC limit 5"")),""1"",""🔴""),""2"",""🟢"")"),"🔴🔴") -> 🔴🔴 | J38: =IFERROR(__xludf.DUMMYFUNCTION("""COMPUTED_VALUE"""),3.0) -> 3 | K38: =IFERROR(__xludf.DUMMYFUNCTION("""COMPUTED_VALUE"""),"Xabi BK") -> Xabi BK | N38: =IFERROR(__xludf.DUMMYFUNCTION("""COMPUTED_VALUE"""),2.0) -> 2 | O38: =IFERROR(__xludf.DUMMYFUNCTION("""COMPUTED_VALUE"""),"Pablo BK") -> Pablo BK
A39: Laura | B39: =COUNT(Partidos!AL2:AL295) -> 6 | C39: =COUNTIF(Partidos!AL2:AL295,">1") -> 3 | D39: =B39+C39 -> 9 | E39: =IF(C39=0,0,C39/B39) -> 0.5 | F39: =IF(B39>($G$3*0.25),1,0) -> 0 | G39: =IFERROR(__xludf.DUMMYFUNCTION("SUBSTITUTE(SUBSTITUTE(TEXTJOIN("""",TRUE,QUERY(Partidos!$A$2:Partidos!$AY$400,""Select AL WHERE AL IS NOT NULL Order By A DESC limit 5"")),""1"",""🔴""),""2"",""🟢"")"),"🟢🟢🔴🟢🔴") -> 🟢🟢🔴🟢🔴 | J39: =IFERROR(__xludf.DUMMYFUNCTION("""COMPUTED_VALUE"""),3.0) -> 3 | K39: =IFERROR(__xludf.DUMMYFUNCTION("""COMPUTED_VALUE"""),"Pablo BK") -> Pablo BK | N39: =IFERROR(__xludf.DUMMYFUNCTION("""COMPUTED_VALUE"""),2.0) -> 2 | O39: =IFERROR(__xludf.DUMMYFUNCTION("""COMPUTED_VALUE"""),"Gio BK") -> Gio BK
A40: David Arg. | B40: =COUNT(Partidos!AM2:AM296) -> 8 | C40: =COUNTIF(Partidos!AM2:AM296,">1") -> 6 | D40: =B40+C40 -> 14 | E40: =IF(C40=0,0,C40/B40) -> 0.75 | F40: =IF(B40>($G$3*0.25),1,0) -> 0 | G40: =IFERROR(__xludf.DUMMYFUNCTION("SUBSTITUTE(SUBSTITUTE(TEXTJOIN("""",TRUE,QUERY(Partidos!$A$2:Partidos!$AY$400,""Select AM WHERE AM IS NOT NULL Order By A DESC limit 5"")),""1"",""🔴""),""2"",""🟢"")"),"🟢🟢🔴🟢🟢") -> 🟢🟢🔴🟢🟢 | J40: =IFERROR(__xludf.DUMMYFUNCTION("""COMPUTED_VALUE"""),3.0) -> 3 | K40: =IFERROR(__xludf.DUMMYFUNCTION("""COMPUTED_VALUE"""),"Javi Temprano") -> Javi Temprano | N40: =IFERROR(__xludf.DUMMYFUNCTION("""COMPUTED_VALUE"""),2.0) -> 2 | O40: =IFERROR(__xludf.DUMMYFUNCTION("""COMPUTED_VALUE"""),"Korta") -> Korta
A41: Íñigo | B41: =COUNT(Partidos!AN2:AN297) -> 4 | C41: =COUNTIF(Partidos!AN2:AN297,">1") -> 3 | D41: =B41+C41 -> 7 | E41: =IF(C41=0,0,C41/B41) -> 0.75 | F41: =IF(B41>($G$3*0.25),1,0) -> 0 | G41: =IFERROR(__xludf.DUMMYFUNCTION("SUBSTITUTE(SUBSTITUTE(TEXTJOIN("""",TRUE,QUERY(Partidos!$A$2:Partidos!$AY$400,""Select AN WHERE AN IS NOT NULL Order By A DESC limit 5"")),""1"",""🔴""),""2"",""🟢"")"),"🟢🔴🟢🟢") -> 🟢🔴🟢🟢 | J41: =IFERROR(__xludf.DUMMYFUNCTION("""COMPUTED_VALUE"""),3.0) -> 3 | K41: =IFERROR(__xludf.DUMMYFUNCTION("""COMPUTED_VALUE"""),"Mikel") -> Mikel | N41: =IFERROR(__xludf.DUMMYFUNCTION("""COMPUTED_VALUE"""),2.0) -> 2 | O41: =IFERROR(__xludf.DUMMYFUNCTION("""COMPUTED_VALUE"""),"Javi Temprano") -> Javi Temprano
A42: Korta | B42: =COUNT(Partidos!AO2:AO298) -> 2 | C42: =COUNTIF(Partidos!AO2:AO298,">1") -> 2 | D42: =B42+C42 -> 4 | E42: =IF(C42=0,0,C42/B42) -> 1 | F42: =IF(B42>($G$3*0.25),1,0) -> 0 | G42: =IFERROR(__xludf.DUMMYFUNCTION("SUBSTITUTE(SUBSTITUTE(TEXTJOIN("""",TRUE,QUERY(Partidos!$A$2:Partidos!$AY$400,""Select AO WHERE AO IS NOT NULL Order By A DESC limit 5"")),""1"",""🔴""),""2"",""🟢"")"),"🟢🟢") -> 🟢🟢 | J42: =IFERROR(__xludf.DUMMYFUNCTION("""COMPUTED_VALUE"""),3.0) -> 3 | K42: =IFERROR(__xludf.DUMMYFUNCTION("""COMPUTED_VALUE"""),"Antonio") -> Antonio | N42: =IFERROR(__xludf.DUMMYFUNCTION("""COMPUTED_VALUE"""),2.0) -> 2 | O42: =IFERROR(__xludf.DUMMYFUNCTION("""COMPUTED_VALUE"""),"Mikel") -> Mikel
...

Sheet Reglas
A1: Campeonato Kostkas 2025/2026
A2: ¿Por qué? Para dar un poco más de vida a esta temporada hacemos un campeonato individual.
A3: Por cada partido jugado 1 punto, ganado 2 puntos. Así se premia la asistencia.
A4: Mínimo partidos de 4x4 a >30 puntos.
A5: Al final de año 2 trofeos: Campéon (más puntos), Regularidad (Mejor porcentaje de victorias)
A6: Se apunta al final de cada día los partidos en una hoja de cálculo compartida.
A7: Si un partido no se acaba por tiempo, pero un equipo va ganando y pasa de 20 puntos, cuenta como victoria.
